Workbook

Sheet Auswertung
A1: Flächenauswertung nach DIN 277:2021 – alle Geschosse
A2: Netto-Raumflächen in m², Bereich a (regulär umschlossen). Quelle: Repository cafm-acw, siehe Blatt „Hinweise“.
A4: Gebäude | B4: Geschoss | C4: Räume | D4: NUF 1 | E4: NUF 2 | F4: NUF 3 | G4: NUF 4 | H4: NUF 5 | I4: NUF 6 | J4: NUF 7 | K4: NUF gesamt | L4: TF | M4: VF | N4: NRF zugeordnet | O4: nicht zugeordnet | P4: NRF gesamt | Q4: Zuordnungs-quote | R4: BGF | S4: KGF
A5: Testgebäude A (TEN-001) | B5: Testgeschoss 01 / 01 | C5: =COUNTIFS(Raumliste!$B$2:$B$153,$A5,Raumliste!$C$2:$C$153,$B5) | D5: =SUMIFS(Raumliste!$G$2:$G$153,Raumliste!$B$2:$B$153,$A5,Raumliste!$C$2:$C$153,$B5,Raumliste!$I$2:$I$153,"NUF 1") | E5: =SUMIFS(Raumliste!$G$2:$G$153,Raumliste!$B$2:$B$153,$A5,Raumliste!$C$2:$C$153,$B5,Raumliste!$I$2:$I$153,"NUF 2") | F5: =SUMIFS(Raumliste!$G$2:$G$153,Raumliste!$B$2:$B$153,$A5,Raumliste!$C$2:$C$153,$B5,Raumliste!$I$2:$I$153,"NUF 3") | G5: =SUMIFS(Raumliste!$G$2:$G$153,Raumliste!$B$2:$B$153,$A5,Raumliste!$C$2:$C$153,$B5,Raumliste!$I$2:$I$153,"NUF 4") | H5: =SUMIFS(Raumliste!$G$2:$G$153,Raumliste!$B$2:$B$153,$A5,Raumliste!$C$2:$C$153,$B5,Raumliste!$I$2:$I$153,"NUF 5") | I5: =SUMIFS(Raumliste!$G$2:$G$153,Raumliste!$B$2:$B$153,$A5,Raumliste!$C$2:$C$153,$B5,Raumliste!$I$2:$I$153,"NUF 6") | J5: =SUMIFS(Raumliste!$G$2:$G$153,Raumliste!$B$2:$B$153,$A5,Raumliste!$C$2:$C$153,$B5,Raumliste!$I$2:$I$153,"NUF 7") | K5: =SUM(D5:J5) | L5: =SUMIFS(Raumliste!$G$2:$G$153,Raumliste!$B$2:$B$153,$A5,Raumliste!$C$2:$C$153,$B5,Raumliste!$I$2:$I$153,"TF") | M5: =SUMIFS(Raumliste!$G$2:$G$153,Raumliste!$B$2:$B$153,$A5,Raumliste!$C$2:$C$153,$B5,Raumliste!$I$2:$I$153,"VF") | N5: =K5+L5+M5 | O5: =SUMIFS(Raumliste!$G$2:$G$153,Raumliste!$B$2:$B$153,$A5,Raumliste!$C$2:$C$153,$B5,Raumliste!$I$2:$I$153,"offen") | P5: =N5+O5 | Q5: =IF(P5=0,0,N5/P5) | R5: n. e. | S5: n. e.
A6: Testgebäude A (TEN-001) | B6: 02 / 1.Obergeschoss | C6: =COUNTIFS(Raumliste!$B$2:$B$153,$A6,Raumliste!$C$2:$C$153,$B6) | D6: =SUMIFS(Raumliste!$G$2:$G$153,Raumliste!$B$2:$B$153,$A6,Raumliste!$C$2:$C$153,$B6,Raumliste!$I$2:$I$153,"NUF 1") | E6: =SUMIFS(Raumliste!$G$2:$G$153,Raumliste!$B$2:$B$153,$A6,Raumliste!$C$2:$C$153,$B6,Raumliste!$I$2:$I$153,"NUF 2") | F6: =SUMIFS(Raumliste!$G$2:$G$153,Raumliste!$B$2:$B$153,$A6,Raumliste!$C$2:$C$153,$B6,Raumliste!$I$2:$I$153,"NUF 3") | G6: =SUMIFS(Raumliste!$G$2:$G$153,Raumliste!$B$2:$B$153,$A6,Raumliste!$C$2:$C$153,$B6,Raumliste!$I$2:$I$153,"NUF 4") | H6: =SUMIFS(Raumliste!$G$2:$G$153,Raumliste!$B$2:$B$153,$A6,Raumliste!$C$2:$C$153,$B6,Raumliste!$I$2:$I$153,"NUF 5") | I6: =SUMIFS(Raumliste!$G$2:$G$153,Raumliste!$B$2:$B$153,$A6,Raumliste!$C$2:$C$153,$B6,Raumliste!$I$2:$I$153,"NUF 6") | J6: =SUMIFS(Raumliste!$G$2:$G$153,Raumliste!$B$2:$B$153,$A6,Raumliste!$C$2:$C$153,$B6,Raumliste!$I$2:$I$153,"NUF 7") | K6: =SUM(D6:J6) | L6: =SUMIFS(Raumliste!$G$2:$G$153,Raumliste!$B$2:$B$153,$A6,Raumliste!$C$2:$C$153,$B6,Raumliste!$I$2:$I$153,"TF") | M6: =SUMIFS(Raumliste!$G$2:$G$153,Raumliste!$B$2:$B$153,$A6,Raumliste!$C$2:$C$153,$B6,Raumliste!$I$2:$I$153,"VF") | N6: =K6+L6+M6 | O6: =SUMIFS(Raumliste!$G$2:$G$153,Raumliste!$B$2:$B$153,$A6,Raumliste!$C$2:$C$153,$B6,Raumliste!$I$2:$I$153,"offen") | P6: =N6+O6 | Q6: =IF(P6=0,0,N6/P6) | R6: n. e. | S6: n. e.
A7: Testgebäude A (TEN-001) | B7: Summe Gebäude | C7: =SUM(C5:C6) | D7: =SUM(D5:D6) | E7: =SUM(E5:E6) | F7: =SUM(F5:F6) | G7: =SUM(G5:G6) | H7: =SUM(H5:H6) | I7: =SUM(I5:I6) | J7: =SUM(J5:J6) | ... P7: =SUM(P5:P6) | Q7: =IF(P7=0,0,N7/P7) | R7: n. e. | S7: n. e.
A8: Testgebäude A (TEN-002) | B8: Testgeschoss 01 / 01 | C8: =COUNTIFS(Raumliste!$B$2:$B$153,$A8,Raumliste!$C$2:$C$153,$B8) | D8: =SUMIFS(Raumliste!$G$2:$G$153,Raumliste!$B$2:$B$153,$A8,Raumliste!$C$2:$C$153,$B8,Raumliste!$I$2:$I$153,"NUF 1") | E8: =SUMIFS(Raumliste!$G$2:$G$153,Raumliste!$B$2:$B$153,$A8,Raumliste!$C$2:$C$153,$B8,Raumliste!$I$2:$I$153,"NUF 2") | F8: =SUMIFS(Raumliste!$G$2:$G$153,Raumliste!$B$2:$B$153,$A8,Raumliste!$C$2:$C$153,$B8,Raumliste!$I$2:$I$153,"NUF 3") | G8: =SUMIFS(Raumliste!$G$2:$G$153,Raumliste!$B$2:$B$153,$A8,Raumliste!$C$2:$C$153,$B8,Raumliste!$I$2:$I$153,"NUF 4") | H8: =SUMIFS(Raumliste!$G$2:$G$153,Raumliste!$B$2:$B$153,$A8,Raumliste!$C$2:$C$153,$B8,Raumliste!$I$2:$I$153,"NUF 5") | I8: =SUMIFS(Raumliste!$G$2:$G$153,Raumliste!$B$2:$B$153,$A8,Raumliste!$C$2:$C$153,$B8,Raumliste!$I$2:$I$153,"NUF 6") | J8: =SUMIFS(Raumliste!$G$2:$G$153,Raumliste!$B$2:$B$153,$A8,Raumliste!$C$2:$C$153,$B8,Raumliste!$I$2:$I$153,"NUF 7") | K8: =SUM(D8:J8) | L8: =SUMIFS(Raumliste!$G$2:$G$153,Raumliste!$B$2:$B$153,$A8,Raumliste!$C$2:$C$153,$B8,Raumliste!$I$2:$I$153,"TF") | M8: =SUMIFS(Raumliste!$G$2:$G$153,Raumliste!$B$2:$B$153,$A8,Raumliste!$C$2:$C$153,$B8,Raumliste!$I$2:$I$153,"VF") | N8: =K8+L8+M8 | O8: =SUMIFS(Raumliste!$G$2:$G$153,Raumliste!$B$2:$B$153,$A8,Raumliste!$C$2:$C$153,$B8,Raumliste!$I$2:$I$153,"offen") | P8: =N8+O8 | Q8: =IF(P8=0,0,N8/P8) | R8: n. e. | S8: n. e.
A9: Testgebäude A (TEN-002) | B9: Summe Gebäude | C9: =SUM(C8:C8) | D9: =SUM(D8:D8) | E9: =SUM(E8:E8) | F9: =SUM(F8:F8) | G9: =SUM(G8:G8) | H9: =SUM(H8:H8) | I9: =SUM(I8:I8) | J9: =SUM(J8:J8) | ... P9: =SUM(P8:P8) | Q9: =IF(P9=0,0,N9/P9) | R9: n. e. | S9: n. e.
A10: DE-SIE-11154 (EG-Zeichnung) | B10: EG | C10: =COUNTIFS(Raumliste!$B$2:$B$153,$A10,Raumliste!$C$2:$C$153,$B10) | D10: =SUMIFS(Raumliste!$G$2:$G$153,Raumliste!$B$2:$B$153,$A10,Raumliste!$C$2:$C$153,$B10,Raumliste!$I$2:$I$153,"NUF 1") | E10: =SUMIFS(Raumliste!$G$2:$G$153,Raumliste!$B$2:$B$153,$A10,Raumliste!$C$2:$C$153,$B10,Raumliste!$I$2:$I$153,"NUF 2") | F10: =SUMIFS(Raumliste!$G$2:$G$153,Raumliste!$B$2:$B$153,$A10,Raumliste!$C$2:$C$153,$B10,Raumliste!$I$2:$I$153,"NUF 3") | G10: =SUMIFS(Raumliste!$G$2:$G$153,Raumliste!$B$2:$B$153,$A10,Raumliste!$C$2:$C$153,$B10,Raumliste!$I$2:$I$153,"NUF 4") | H10: =SUMIFS(Raumliste!$G$2:$G$153,Raumliste!$B$2:$B$153,$A10,Raumliste!$C$2:$C$153,$B10,Raumliste!$I$2:$I$153,"NUF 5") | I10: =SUMIFS(Raumliste!$G$2:$G$153,Raumliste!$B$2:$B$153,$A10,Raumliste!$C$2:$C$153,$B10,Raumliste!$I$2:$I$153,"NUF 6") | J10: =SUMIFS(Raumliste!$G$2:$G$153,Raumliste!$B$2:$B$153,$A10,Raumliste!$C$2:$C$153,$B10,Raumliste!$I$2:$I$153,"NUF 7") | K10: =SUM(D10:J10) | L10: =SUMIFS(Raumliste!$G$2:$G$153,Raumliste!$B$2:$B$153,$A10,Raumliste!$C$2:$C$153,$B10,Raumliste!$I$2:$I$153,"TF") | M10: =SUMIFS(Raumliste!$G$2:$G$153,Raumliste!$B$2:$B$153,$A10,Raumliste!$C$2:$C$153,$B10,Raumliste!$I$2:$I$153,"VF") | N10: =K10+L10+M10 | O10: =SUMIFS(Raumliste!$G$2:$G$153,Raumliste!$B$2:$B$153,$A10,Raumliste!$C$2:$C$153,$B10,Raumliste!$I$2:$I$153,"offen") | P10: =N10+O10 | Q10: =IF(P10=0,0,N10/P10) | R10: n. e. | S10: n. e.
A11: DE-SIE-11154 (EG-Zeichnung) | B11: Summe Gebäude | C11: =SUM(C10:C10) | D11: =SUM(D10:D10) | E11: =SUM(E10:E10) | F11: =SUM(F10:F10) | G11: =SUM(G10:G10) | H11: =SUM(H10:H10) | I11: =SUM(I10:I10) | J11: =SUM(J10:J10) | ... P11: =SUM(P10:P10) | Q11: =IF(P11=0,0,N11/P11) | R11: n. e. | S11: n. e.
A12: Gesamt alle Gebäude / Geschosse | C12: =C7+C9+C11 | D12: =D7+D9+D11 | E12: =E7+E9+E11 | F12: =F7+F9+F11 | G12: =G7+G9+G11 | H12: =H7+H9+H11 | I12: =I7+I9+I11 | J12: =J7+J9+J11 | ... P12: =P7+P9+P11 | Q12: =IF(P12=0,0,N12/P12) | R12: n. e. | S12: n. e.
A14: Kennzahlen je Gebäude
A15: Gebäude | B15: NUF / NRF | C15: VF / NUF | D15: TF / NRF | E15: Anteil NUF 2 Büro an NUF | F15: Räume zu prüfen
A16: =A7 | B16: =IF(N7=0,0,K7/N7) | C16: =IF(K7=0,0,M7/K7) | D16: =IF(N7=0,0,L7/N7) | E16: =IF(K7=0,0,E7/K7) | F16: =COUNTIFS(Raumliste!$B$2:$B$153,A7,Raumliste!$K$2:$K$153,"ja")
A17: =A9 | B17: =IF(N9=0,0,K9/N9) | C17: =IF(K9=0,0,M9/K9) | D17: =IF(N9=0,0,L9/N9) | E17: =IF(K9=0,0,E9/K9) | F17: =COUNTIFS(Raumliste!$B$2:$B$153,A9,Raumliste!$K$2:$K$153,"ja")
A18: =A11 | B18: =IF(N11=0,0,K11/N11) | C18: =IF(K11=0,0,M11/K11) | D18: =IF(N11=0,0,L11/N11) | E18: =IF(K11=0,0,E11/K11) | F18: =COUNTIFS(Raumliste!$B$2:$B$153,A11,Raumliste!$K$2:$K$153,"ja")
A19: Bezugsgröße der Quoten: zugeordnete NRF (nicht zugeordnete Räume bleiben außen vor).

Sheet Raumliste
A1: Quelle | B1: Gebäude | C1: Geschoss | D1: Raumnr. | E1: Bezeichnung | F1: Nutzungsart (CAFM) | G1: NRF [m²] | H1: DIN 277 Code | I1: Hauptgruppe | J1: Zuordnung über | K1: prüfen | L1: Bemerkung
A2: CAFM TEN-001 | B2: Testgebäude A (TEN-001) | C2: Testgeschoss 01 / 01 | D2: 101 | E2: Testraum 101 | F2: Büro | H2: NUF 2.1 | I2: =IF(LEFT(H2,3)="NUF",LEFT(H2,5),IF(LEFT(H2,2)="TF","TF",IF(LEFT(H2,2)="VF","VF","offen"))) | J2: CAFM-Nutzungsart | K2: ja | L2: Netto-Raumfläche fehlt
A3: CAFM TEN-001 | B3: Testgebäude A (TEN-001) | C3: 02 / 1.Obergeschoss | D3: 025 | E3: Büro | F3: Büro | G3: 34 | H3: NUF 2.1 | I3: =IF(LEFT(H3,3)="NUF",LEFT(H3,5),IF(LEFT(H3,2)="TF","TF",IF(LEFT(H3,2)="VF","VF","offen"))) | J3: CAFM-Nutzungsart | K3: nein
A4: CAFM TEN-001 | B4: Testgebäude A (TEN-001) | C4: Testgeschoss 01 / 01 | D4: 026 | E4: Büro | F4: Büro | G4: 18.87 | H4: NUF 2.1 | I4: =IF(LEFT(H4,3)="NUF",LEFT(H4,5),IF(LEFT(H4,2)="TF","TF",IF(LEFT(H4,2)="VF","VF","offen"))) | J4: CAFM-Nutzungsart | K4: nein
A5: CAFM TEN-001 | B5: Testgebäude A (TEN-001) | C5: Testgeschoss 01 / 01 | D5: 027 | E5: Büro | F5: Büro | G5: 18.79 | H5: NUF 2.1 | I5: =IF(LEFT(H5,3)="NUF",LEFT(H5,5),IF(LEFT(H5,2)="TF","TF",IF(LEFT(H5,2)="VF","VF","offen"))) | J5: CAFM-Nutzungsart | K5: nein
A6: CAFM TEN-001 | B6: Testgebäude A (TEN-001) | C6: Testgeschoss 01 / 01 | D6: 028 | E6: Büro | F6: Büro | G6: 32.2 | H6: NUF 2.1 | I6: =IF(LEFT(H6,3)="NUF",LEFT(H6,5),IF(LEFT(H6,2)="TF","TF",IF(LEFT(H6,2)="VF","VF","offen"))) | J6: CAFM-Nutzungsart | K6: nein
A7: CAFM TEN-001 | B7: Testgebäude A (TEN-001) | C7: Testgeschoss 01 / 01 | D7: 029 | E7: Büro | F7: Büro | G7: 18.79 | H7: NUF 2.1 | I7: =IF(LEFT(H7,3)="NUF",LEFT(H7,5),IF(LEFT(H7,2)="TF","TF",IF(LEFT(H7,2)="VF","VF","offen"))) | J7: CAFM-Nutzungsart | K7: nein
A8: CAFM TEN-001 | B8: Testgebäude A (TEN-001) | C8: Testgeschoss 01 / 01 | D8: 030 | E8: Büro | F8: Büro | G8: 32.2 | H8: NUF 2.1 | I8: =IF(LEFT(H8,3)="NUF",LEFT(H8,5),IF(LEFT(H8,2)="TF","TF",IF(LEFT(H8,2)="VF","VF","offen"))) | J8: CAFM-Nutzungsart | K8: nein
A9: CAFM TEN-001 | B9: Testgebäude A (TEN-001) | C9: Testgeschoss 01 / 01 | D9: 031 | E9: Büro | F9: Büro | G9: 18.79 | H9: NUF 2.1 | I9: =IF(LEFT(H9,3)="NUF",LEFT(H9,5),IF(LEFT(H9,2)="TF","TF",IF(LEFT(H9,2)="VF","VF","offen"))) | J9: CAFM-Nutzungsart | K9: nein
A10: CAFM TEN-001 | B10: Testgebäude A (TEN-001) | C10: Testgeschoss 01 / 01 | D10: 032 | E10: Büro | F10: Büro | G10: 19 | H10: NUF 2.1 | I10: =IF(LEFT(H10,3)="NUF",LEFT(H10,5),IF(LEFT(H10,2)="TF","TF",IF(LEFT(H10,2)="VF","VF","offen"))) | J10: CAFM-Nutzungsart | K10: nein
A11: CAFM TEN-001 | B11: Testgebäude A (TEN-001) | C11: Testgeschoss 01 / 01 | D11: 024 | E11: Büro | F11: Büro | G11: 18.82 | H11: NUF 2.1 | I11: =IF(LEFT(H11,3)="NUF",LEFT(H11,5),IF(LEFT(H11,2)="TF","TF",IF(LEFT(H11,2)="VF","VF","offen"))) | J11: CAFM-Nutzungsart | K11: nein
A12: CAFM TEN-001 | B12: Testgebäude A (TEN-001) | C12: Testgeschoss 01 / 01 | D12: 023 | E12: Büro | F12: Büro | G12: 18.96 | H12: NUF 2.1 | I12: =IF(LEFT(H12,3)="NUF",LEFT(H12,5),IF(LEFT(H12,2)="TF","TF",IF(LEFT(H12,2)="VF","VF","offen"))) | J12: CAFM-Nutzungsart | K12: nein
A13: CAFM TEN-001 | B13: Testgebäude A (TEN-001) | C13: Testgeschoss 01 / 01 | D13: 022b | E13: Büro | F13: Büro | G13: 18.92 | H13: NUF 2.1 | I13: =IF(LEFT(H13,3)="NUF",LEFT(H13,5),IF(LEFT(H13,2)="TF","TF",IF(LEFT(H13,2)="VF","VF","offen"))) | J13: CAFM-Nutzungsart | K13: nein
A14: CAFM TEN-001 | B14: Testgebäude A (TEN-001) | C14: Testgeschoss 01 / 01 | D14: 022a | E14: Büro | F14: Büro | G14: 18.92 | H14: NUF 2.1 | I14: =IF(LEFT(H14,3)="NUF",LEFT(H14,5),IF(LEFT(H14,2)="TF","TF",IF(LEFT(H14,2)="VF","VF","offen"))) | J14: CAFM-Nutzungsart | K14: nein
... A28: CAFM TEN-001 | B28: Testgebäude A (TEN-001) | C28: Testgeschoss 01 / 01 | D28: 043 | E28: Büro | F28: Büro | G28: 19.27 | H28: NUF 2.1 | I28: =IF(LEFT(H28,3)="NUF",LEFT(H28,5),IF(LEFT(H28,2)="TF","TF",IF(LEFT(H28,2)="VF","VF","offen"))) | J28: CAFM-Nutzungsart | K28: nein
A29: CAFM TEN-002 | B29: Testgebäude A (TEN-002) | C29: Testgeschoss 01 / 01 | D29: 101 | E29: Testraum 101 | F29: Büro | H29: NUF 2.1 | I29: =IF(LEFT(H29,3)="NUF",LEFT(H29,5),IF(LEFT(H29,2)="TF","TF",IF(LEFT(H29,2)="VF","VF","offen"))) | J29: CAFM-Nutzungsart | K29: ja | L29: Netto-Raumfläche fehlt
A30: DWG-Import F3.2 | B30: DE-SIE-11154 (EG-Zeichnung) | C30: EG | D30: 32-15 | G30: 3.54 | H30: offen | I30: =IF(LEFT(H30,3)="NUF",LEFT(H30,5),IF(LEFT(H30,2)="TF","TF",IF(LEFT(H30,2)="VF","VF","offen"))) | J30: keine Bezeichnung | K30: ja
A31: DWG-Import F3.2 | B31: DE-SIE-11154 (EG-Zeichnung) | C31: EG | D31: 32-13.1 | G31: 7.27 | H31: offen | I31: =IF(LEFT(H31,3)="NUF",LEFT(H31,5),IF(LEFT(H31,2)="TF","TF",IF(LEFT(H31,2)="VF","VF","offen"))) | J31: keine Bezeichnung | K31: ja
A32: DWG-Import F3.2 | B32: DE-SIE-11154 (EG-Zeichnung) | C32: EG | D32: 32-14 | E32: PZ. | G32: 3.54 | H32: offen | I32: =IF(LEFT(H32,3)="NUF",LEFT(H32,5),IF(LEFT(H32,2)="TF","TF",IF(LEFT(H32,2)="VF","VF","offen"))) | J32: Bezeichnung nicht eindeutig | K32: ja
A33: DWG-Import F3.2 | B33: DE-SIE-11154 (EG-Zeichnung) | C33: EG | D33: 32-13 | G33: 6.03 | H33: offen | I33: =IF(LEFT(H33,3)="NUF",LEFT(H33,5),IF(LEFT(H33,2)="TF","TF",IF(LEFT(H33,2)="VF","VF","offen"))) | J33: keine Bezeichnung | K33: ja
A34: DWG-Import F3.2 | B34: DE-SIE-11154 (EG-Zeichnung) | C34: EG | D34: 32-13.2 | E34: Stiefel Waschen | G34: 3.49 | H34: NUF 7.1 | I34: =IF(LEFT(H34,3)="NUF",LEFT(H34,5),IF(LEFT(H34,2)="TF","TF",IF(LEFT(H34,2)="VF","VF","offen"))) | J34: Bezeichnung | K34: nein
A35: DWG-Import F3.2 | B35: DE-SIE-11154 (EG-Zeichnung) | C35: EG | D35: 32-7.1 | G35: 7.33 | H35: offen | I35: =IF(LEFT(H35,3)="NUF",LEFT(H35,5),IF(LEFT(H35,2)="TF","TF",IF(LEFT(H35,2)="VF","VF","offen"))) | J35: keine Bezeichnung | K35: ja
A36: DWG-Import F3.2 | B36: DE-SIE-11154 (EG-Zeichnung) | C36: EG | D36: 32-11 | E36: Waschen | G36: 14.76 | H36: NUF 7.1 | I36: =IF(LEFT(H36,3)="NUF",LEFT(H36,5),IF(LEFT(H36,2)="TF","TF",IF(LEFT(H36,2)="VF","VF","offen"))) | J36: Bezeichnung | K36: nein
A37: DWG-Import F3.2 | B37: DE-SIE-11154 (EG-Zeichnung) | C37: EG | D37: 32-10 | E37: Dusche | G37: 6.54 | H37: NUF 7.1 | I37: =IF(LEFT(H37,3)="NUF",LEFT(H37,5),IF(LEFT(H37,2)="TF","TF",IF(LEFT(H37,2)="VF","VF","offen"))) | J37: Bezeichnung | K37: nein
A38: DWG-Import F3.2 | B38: DE-SIE-11154 (EG-Zeichnung) | C38: EG | D38: 32-12 | G38: 21.68 | H38: offen | I38: =IF(LEFT(H38,3)="NUF",LEFT(H38,5),IF(LEFT(H38,2)="TF","TF",IF(LEFT(H38,2)="VF","VF","offen"))) | J38: keine Bezeichnung | K38: ja
A39: DWG-Import F3.2 | B39: DE-SIE-11154 (EG-Zeichnung) | C39: EG | D39: 23 | G39: 19.38 | H39: offen | I39: =IF(LEFT(H39,3)="NUF",LEFT(H39,5),IF(LEFT(H39,2)="TF","TF",IF(LEFT(H39,2)="VF","VF","offen"))) | J39: keine Bezeichnung | K39: ja
A40: DWG-Import F3.2 | B40: DE-SIE-11154 (EG-Zeichnung) | C40: EG | D40: 22 | G40: 18.61 | H40: offen | I40: =IF(LEFT(H40,3)="NUF",LEFT(H40,5),IF(LEFT(H40,2)="TF","TF",IF(LEFT(H40,2)="VF","VF","offen"))) | J40: keine Bezeichnung | K40: ja
A41: DWG-Import F3.2 | B41: DE-SIE-11154 (EG-Zeichnung) | C41: EG | D41: 25 | E41: Aufenthaltsraum | G41: 28.3 | H41: NUF 1.3 | I41: =IF(LEFT(H41,3)="NUF",LEFT(H41,5),IF(LEFT(H41,2)="TF","TF",IF(LEFT(H41,2)="VF","VF","offen"))) | J41: Bezeichnung | K41: nein
A42: DWG-Import F3.2 | B42: DE-SIE-11154 (EG-Zeichnung) | C42: EG | D42: 27 | G42: 28.56 | H42: offen | I42: =IF(LEFT(H42,3)="NUF",LEFT(H42,5),IF(LEFT(H42,2)="TF","TF",IF(LEFT(H42,2)="VF","VF","offen"))) | J42: keine Bezeichnung | K42: ja
A43: DWG-Import F3.2 | B43: DE-SIE-11154 (EG-Zeichnung) | C43: EG | D43: 20 | G43: 18.87 | H43: offen | I43: =IF(LEFT(H43,3)="NUF",LEFT(H43,5),IF(LEFT(H43,2)="TF","TF",IF(LEFT(H43,2)="VF","VF","offen"))) | J43: keine Bezeichnung | K43: ja
A44: DWG-Import F3.2 | B44: DE-SIE-11154 (EG-Zeichnung) | C44: EG | D44: 21 | G44: 28.3 | H44: offen | I44: =IF(LEFT(H44,3)="NUF",LEFT(H44,5),IF(LEFT(H44,2)="TF","TF",IF(LEFT(H44,2)="VF","VF","offen"))) | J44: keine Bezeichnung | K44: ja
A45: DWG-Import F3.2 | B45: DE-SIE-11154 (EG-Zeichnung) | C45: EG | D45: 19 | G45: 20.14 | H45: offen | I45: =IF(LEFT(H45,3)="NUF",LEFT(H45,5),IF(LEFT(H45,2)="TF","TF",IF(LEFT(H45,2)="VF","VF","offen"))) | J45: keine Bezeichnung | K45: ja
A46: DWG-Import F3.2 | B46: DE-SIE-11154 (EG-Zeichnung) | C46: EG | D46: 24 | G46: 46.39 | H46: offen | I46: =IF(LEFT(H46,3)="NUF",LEFT(H46,5),IF(LEFT(H46,2)="TF","TF",IF(LEFT(H46,2)="VF","VF","offen"))) | J46: keine Bezeichnung | K46: ja
A47: DWG-Import F3.2 | B47: DE-SIE-11154 (EG-Zeichnung) | C47: EG | D47: 24.1 | G47: 5.88 | H47: offen | I47: =IF(LEFT(H47,3)="NUF",LEFT(H47,5),IF(LEFT(H47,2)="TF","TF",IF(LEFT(H47,2)="VF","VF","offen"))) | J47: keine Bezeichnung | K47: ja
A48: DWG-Import F3.2 | B48: DE-SIE-11154 (EG-Zeichnung) | C48: EG | D48: 32-1 | E48: Anlieferung | G48: 29.93 | H48: NUF 4.4 | I48: =IF(LEFT(H48,3)="NUF",LEFT(H48,5),IF(LEFT(H48,2)="TF","TF",IF(LEFT(H48,2)="VF","VF","offen"))) | J48: Bezeichnung | K48: nein
A49: DWG-Import F3.2 | B49: DE-SIE-11154 (EG-Zeichnung) | C49: EG | D49: 32 | E49: Funkwerkstatt | G49: 28.05 | H49: NUF 3.2 | I49: =IF(LEFT(H49,3)="NUF",LEFT(H49,5),IF(LEFT(H49,2)="TF","TF",IF(LEFT(H49,2)="VF","VF","offen"))) | J49: Bezeichnung | K49: nein
A50: DWG-Import F3.2 | B50: DE-SIE-11154 (EG-Zeichnung) | C50: EG | D50: 28 | G50: 18.87 | H50: offen | I50: =IF(LEFT(H50,3)="NUF",LEFT(H50,5),IF(LEFT(H50,2)="TF","TF",IF(LEFT(H50,2)="VF","VF","offen"))) | J50: keine Bezeichnung | K50: ja
A51: DWG-Import F3.2 | B51: DE-SIE-11154 (EG-Zeichnung) | C51: EG | D51: 29 | G51: 18.61 | H51: offen | I51: =IF(LEFT(H51,3)="NUF",LEFT(H51,5),IF(LEFT(H51,2)="TF","TF",IF(LEFT(H51,2)="VF","VF","offen"))) | J51: keine Bezeichnung | K51: ja
A52: DWG-Import F3.2 | B52: DE-SIE-11154 (EG-Zeichnung) | C52: EG | D52: 30 | G52: 18.61 | H52: offen | I52: =IF(LEFT(H52,3)="NUF",LEFT(H52,5),IF(LEFT(H52,2)="TF","TF",IF(LEFT(H52,2)="VF","VF","offen"))) | J52: keine Bezeichnung | K52: ja
A53: DWG-Import F3.2 | B53: DE-SIE-11154 (EG-Zeichnung) | C53: EG | D53: 31 | G53: 18.87 | H53: offen | I53: =IF(LEFT(H53,3)="NUF",LEFT(H53,5),IF(LEFT(H53,2)="TF","TF",IF(LEFT(H53,2)="VF","VF","offen"))) | J53: keine Bezeichnung | K53: ja
...

Sheet DIN277-Katalog
A1: Code | B1: Bezeichnung (DIN 277:2021, Auszug)
A2: NUF 1.1 | B2: Wohnräume
A3: NUF 1.2 | B3: Gemeinschaftsräume
A4: NUF 1.3 | B4: Pausenräume
A5: NUF 1.4 | B5: Warteräume
A6: NUF 1.5 | B6: Speiseräume
A7: NUF 2.1 | B7: Büroräume
A8: NUF 2.2 | B8: Großraumbüros
A9: NUF 2.3 | B9: Besprechungsräume
A10: NUF 3.2 | B10: Werkstätten
A11: NUF 3.7 | B11: Küchen
A12: NUF 3.8 | B12: Sonderarbeitsräume
... A26: offen | B26: noch nicht zugeordnet

Sheet Hinweise
A1: Thema | B1: Hinweis
A2: Gegenstand | B2: Flächenauswertung nach DIN 277:2021 (Grundflächen und Rauminhalte im Hochbau) über alle Geschosse, die im Repository cafm-acw mit Flächendaten vorliegen.
A3: Quelle A | B3: backend/seed/app_state_live.json – CAFM-Datenstand, Mandant TEN-001 (Testliegenschaft Alpha / Testgebäude A, Geschosse 01 und 02). Fläche = Merkmal „Netto-Raumfläche“, Zuordnung über Merkmal „Nutzungsart“. TEN-002 enthält nur einen Testraum ohne Fläche, TEN-003 keine Objekte.
A4: Quelle B | B4: docs/test-results/F3.2_AEC_Muster_Ergebnis.json – Ergebnis des AEC-Flächenimports der Zeichnung DE-SIE-11154-04-02-01_EG (124 AecDbSpaces, Layer A_Raeume). Fläche = aecArea. In der Zeichnung liegt nur das Erdgeschoss vor.
A5: Zuordnung | B5: DIN-277-Codes wurden aus Raumbezeichnung bzw. Nutzungsart abgeleitet. Untergruppen (z. B. NUF 2.1) sind Vorschläge; Hauptgruppen (NUF 1–7, TF, VF) sind für die Auswertung maßgeblich. Räume mit unklarer Bezeichnung sind in der Raumliste mit „prüfen = ja“ markiert.
A6: Nicht zugeordnet | B6: Der Großteil der DWG-Räume hat keine Raumbezeichnung (Property „Name“ leer). Diese Räume stehen auf „offen“ und erscheinen in der Spalte „nicht zugeordnet“. Sobald der Code in Raumliste!H gesetzt wird, rechnet die Auswertung neu.
A7: BGF / KGF | B7: Nicht ermittelbar (n. e.): Beide Quellen enthalten nur Raumflächen (NRF), keine Geschossumrisse, Wand- oder Konstruktionsflächen. Für BGF = NRF + KGF wird ein BGF-Polygon je Geschoss (DWG-Layer oder CAFM-Merkmal) benötigt.
A8: Bereiche a/b/c | B8: Alle Flächen wurden als Bereich a (regulär umschlossen) gewertet; Balkone, Loggien o. Ä. sind in den Quellen nicht gekennzeichnet.
A9: Datenqualität | B9: Geschoss OBJ-031: Name „02“ und Nummer „1.Obergeschoss“ sind im CAFM vertauscht gepflegt. Raum 101 (Testraum) hat keine Netto-Raumfläche. DWG-Raum 0069 hat die Nummer „??“. Das DWG-Property „OKFFB“ enthält Ziffern 1–9, die keiner DIN-277-Gruppe konsistent entsprechen (z. B. Büros = 1) und wurden daher nicht verwendet. Umlaute aus der DWG (CP850) wurden korrigiert.
A10: Systemabgleich | B10: Das CAFM ACW kennt DIN 277 bisher als zentral gepflegten Systemkatalog, als Merkmal „DIN-277-Kategorie“ (Freitext beim BIM-Import) und für Piktogramme. Eine fertige DIN-277-Auswertung je Geschoss gibt es im System noch nicht; das Mandantenmerkmal „Nutzungsart“ nutzt aktuell einen Testkatalog (Büro, Besprechung, Technik).
A11: Bedienung | B11: Gelbe Zellen in Raumliste!H sind die einzigen Eingabezellen (Dropdown aus Blatt „DIN277-Katalog“). Alle Summen und Kennzahlen sind Formeln.
